<?xml version="1.0"?>
<robot xmlns:xacro="http://www.ros.org/wiki/xacro">
  <xacro:include filename="$(find kuka_resources)/urdf/common_constants.xacro"/>

  <xacro:macro name="kuka_kr6r900sixx" params="prefix">
    <link name="${prefix}base_link">
      <visual>
        <origin xyz="0 0 0" rpy="0 0 0"/>
        <geometry>
          <mesh filename="package://kuka_kr6_support/meshes/kr6_agilus/visual/base_link.dae" />
        </geometry>
      </visual>
      <collision>
        <origin xyz="0 0 0" rpy="0 0 0"/>
        <geometry>
          <mesh filename="package://kuka_kr6_support/meshes/kr6_agilus/collision/base_link.stl" />
        </geometry>
      </collision>
      <inertial>
          <origin xyz="0 0 0" rpy="0 0 0" />
          <mass value="0.1" />
          <inertia
            ixx="1.0" ixy="0.0" ixz="0.0"
                      iyy="1.0" iyz="0.0"
                                izz="1.0" />
      </inertial>
    </link>
    <link name="${prefix}link_1">
      <visual>
        <origin xyz="0 0 0" rpy="0 0 0"/>
        <geometry>
          <mesh filename="package://kuka_kr6_support/meshes/kr6_agilus/visual/link_1.dae" />
        </geometry>
      </visual>
      <collision>
        <origin xyz="0 0 0" rpy="0 0 0"/>
        <geometry>
          <mesh filename="package://kuka_kr6_support/meshes/kr6_agilus/collision/link_1.stl" />
        </geometry>
      </collision>
      <inertial>
          <origin xyz="0 0 0" rpy="0 0 0" />
          <mass value="0.1" />
          <inertia
            ixx="1.0" ixy="0.0" ixz="0.0"
                      iyy="1.0" iyz="0.0"
                                izz="1.0" />
      </inertial>
    </link>
    <link name="${prefix}link_2">
      <visual>
        <origin xyz="0 0 0" rpy="0 0 0"/>
        <geometry>
          <mesh filename="package://kuka_kr6_support/meshes/kr6r900sixx/visual/link_2.dae"/>
        </geometry>
      </visual>
      <collision>
        <origin xyz="0 0 0" rpy="0 0 0"/>
        <geometry>
          <mesh filename="package://kuka_kr6_support/meshes/kr6r900sixx/collision/link_2.stl" />
        </geometry>
      </collision>
      <inertial>
          <origin xyz="0 0 0" rpy="0 0 0" />
          <mass value="0.1" />
          <inertia
            ixx="1.0" ixy="0.0" ixz="0.0"
                      iyy="1.0" iyz="0.0"
                                izz="1.0" />
      </inertial>
    </link>
    <link name="${prefix}link_3">
      <visual>
        <origin xyz="0 0 0" rpy="0 0 0"/>
        <geometry>
          <mesh filename="package://kuka_kr6_support/meshes/kr6_agilus/visual/link_3.dae" />
        </geometry>
      </visual>
      <collision>
        <origin xyz="0 0 0" rpy="0 0 0"/>
        <geometry>
          <mesh filename="package://kuka_kr6_support/meshes/kr6_agilus/collision/link_3.stl" />
        </geometry>
      </collision>
      <inertial>
          <origin xyz="0 0 0" rpy="0 0 0" />
          <mass value="0.1" />
          <inertia
            ixx="1.0" ixy="0.0" ixz="0.0"
                      iyy="1.0" iyz="0.0"
                                izz="1.0" />
      </inertial>
    </link>
    <link name="${prefix}link_4">
      <visual>
        <origin xyz="0 0 0" rpy="0 0 0"/>
        <geometry>
          <mesh filename="package://kuka_kr6_support/meshes/kr6r900sixx/visual/link_4.dae" />
        </geometry>
      </visual>
      <collision>
        <origin xyz="0 0 0" rpy="0 0 0"/>
        <geometry>
          <mesh filename="package://kuka_kr6_support/meshes/kr6r900sixx/collision/link_4.stl" />
        </geometry>
      </collision>
      <inertial>
          <origin xyz="0 0 0" rpy="0 0 0" />
          <mass value="0.1" />
          <inertia
            ixx="1.0" ixy="0.0" ixz="0.0"
                      iyy="1.0" iyz="0.0"
                                izz="1.0" />
      </inertial>
    </link>
    <link name="${prefix}link_5">
      <visual>
        <origin xyz="0 0 0" rpy="0 0 0"/>
        <geometry>
          <mesh filename="package://kuka_kr6_support/meshes/kr6_agilus/visual/link_5.dae" />
        </geometry>
      </visual>
      <collision>
        <origin xyz="0 0 0" rpy="0 0 0"/>
        <geometry>
          <mesh filename="package://kuka_kr6_support/meshes/kr6_agilus/collision/link_5.stl" />
        </geometry>
      </collision>
      <inertial>
          <origin xyz="0 0 0" rpy="0 0 0" />
          <mass value="0.1" />
          <inertia
            ixx="1.0" ixy="0.0" ixz="0.0"
                      iyy="1.0" iyz="0.0"
                                izz="1.0" />
      </inertial>
    </link>
    <link name="${prefix}link_6">
      <visual>
        <origin xyz="0 0 0" rpy="0 0 0"/>
        <geometry>
          <mesh filename="package://kuka_kr6_support/meshes/kr6_agilus/visual/link_6.dae" />
        </geometry>
      </visual>
      <collision>
        <origin xyz="0 0 0" rpy="0 0 0"/>
        <geometry>
          <mesh filename="package://kuka_kr6_support/meshes/kr6_agilus/collision/link_6.stl" />
        </geometry>
      </collision>
      <inertial>
          <origin xyz="0 0 0" rpy="0 0 0" />
          <mass value="0.1" />
          <inertia
            ixx="1.0" ixy="0.0" ixz="0.0"
                      iyy="1.0" iyz="0.0"
                                izz="1.0" />
      </inertial>
    </link>
    <!-- This frame corresponds to the $FLANGE coordinate system in KUKA KRC controllers. -->
    <link name="${prefix}tool0"/>

    <joint name="${prefix}joint_a1" type="revolute">
      <origin xyz="0 0 0.400" rpy="0 0 0"/>
      <parent link="${prefix}base_link"/>
      <child link="${prefix}link_1"/>
      <axis xyz="0 0 -1"/>
      <limit effort="0" lower="${-DEG2RAD * 170}" upper="${DEG2RAD * 170}" velocity="${DEG2RAD * 360}"/>
      <dynamics damping="100.0" friction="100.0"/>
    </joint>
    <joint name="${prefix}joint_a2" type="revolute">
      <origin xyz="0.025 0 0" rpy="0 0 0"/>
      <parent link="${prefix}link_1"/>
      <child link="${prefix}link_2"/>
      <axis xyz="0 1 0"/>
      <limit effort="0" lower="${-DEG2RAD * 190}" upper="${DEG2RAD * 45}" velocity="${DEG2RAD * 300}"/>
      <dynamics damping="100.0" friction="100.0"/>
    </joint>
    <joint name="${prefix}joint_a3" type="revolute">
      <origin xyz="0.455 0 0" rpy="0 0 0"/>
      <parent link="${prefix}link_2"/>
      <child link="${prefix}link_3"/>
      <axis xyz="0 1 0"/>
      <limit effort="0" lower="${-DEG2RAD * 120}" upper="${DEG2RAD * 156}" velocity="${DEG2RAD * 360}"/>
      <dynamics damping="100.0" friction="100.0"/>
    </joint>
    <joint name="${prefix}joint_a4" type="revolute">
      <origin xyz="0 0 0.035" rpy="0 0 0"/>
      <parent link="${prefix}link_3"/>
      <child link="${prefix}link_4"/>
      <axis xyz="-1 0 0"/>
      <limit effort="0" lower="${-DEG2RAD * 185}" upper="${DEG2RAD * 185}" velocity="${DEG2RAD * 381}"/>
      <dynamics damping="100.0" friction="100.0"/>
    </joint>
    <joint name="${prefix}joint_a5" type="revolute">
      <origin xyz="0.420 0 0" rpy="0 0 0"/>
      <parent link="${prefix}link_4"/>
      <child link="${prefix}link_5"/>
      <axis xyz="0 1 0"/>
      <limit effort="0" lower="${-DEG2RAD * 120}" upper="${DEG2RAD * 120}" velocity="${DEG2RAD * 388}"/>
      <dynamics damping="100.0" friction="100.0"/>
    </joint>
    <joint name="${prefix}joint_a6" type="revolute">
      <origin xyz="0.080 0 0" rpy="0 0 0"/>
      <parent link="${prefix}link_5"/>
      <child link="${prefix}link_6"/>
      <axis xyz="-1 0 0"/>
      <limit effort="0" lower="${-DEG2RAD * 350}" upper="${DEG2RAD * 350}" velocity="${DEG2RAD * 615}"/>
      <dynamics damping="100.0" friction="100.0"/>
    </joint>
    <joint name="${prefix}joint_a6-tool0" type="fixed">
      <parent link="${prefix}link_6"/>
      <child link="${prefix}tool0"/>
      <origin xyz="0 0 0" rpy="0 ${DEG2RAD * 90} 0"/>
    </joint>

    <!-- ROS base_link to KUKA $ROBROOT coordinate system transform -->
    <link name="${prefix}base" />
    <joint name="${prefix}base_link-base" type="fixed">
      <origin xyz="0 0 0" rpy="0 0 0"/>
      <parent link="${prefix}base_link"/>
      <child link="${prefix}base"/>
    </joint>


    <transmission name="${prefix}joint_a1_trans">
      <type>transmission_interface/SimpleTransmission</type>
      <joint name="${prefix}joint_a1">
        <hardwareInterface>PositionJointInterface</hardwareInterface>
      </joint>
      <actuator name="${prefix}joint_a1_motor">
        <mechanicalReduction>1</mechanicalReduction>
      </actuator>
    </transmission>
    <transmission name="${prefix}joint_a2_trans">
      <type>transmission_interface/SimpleTransmission</type>
      <joint name="${prefix}joint_a2">
        <hardwareInterface>PositionJointInterface</hardwareInterface>
      </joint>
      <actuator name="${prefix}joint_a2_motor">
        <mechanicalReduction>1</mechanicalReduction>
      </actuator>
    </transmission>
    <transmission name="${prefix}joint_a3_trans">
      <type>transmission_interface/SimpleTransmission</type>
      <joint name="${prefix}joint_a3">
        <hardwareInterface>PositionJointInterface</hardwareInterface>
      </joint>
      <actuator name="${prefix}joint_a3_motor">
        <mechanicalReduction>1</mechanicalReduction>
      </actuator>
    </transmission>
    <transmission name="${prefix}joint_a4_trans">
      <type>transmission_interface/SimpleTransmission</type>
      <joint name="${prefix}joint_a4">
        <hardwareInterface>PositionJointInterface</hardwareInterface>
      </joint>
      <actuator name="${prefix}joint_a4_motor">
        <mechanicalReduction>1</mechanicalReduction>
      </actuator>
    </transmission>
    <transmission name="${prefix}joint_a5_trans">
      <type>transmission_interface/SimpleTransmission</type>
      <joint name="${prefix}joint_a5">
        <hardwareInterface>PositionJointInterface</hardwareInterface>
      </joint>
      <actuator name="${prefix}joint_a5_motor">
        <mechanicalReduction>1</mechanicalReduction>
      </actuator>
    </transmission>
    <transmission name="${prefix}joint_a6_trans">
      <type>transmission_interface/SimpleTransmission</type>
      <joint name="${prefix}joint_a6">
        <hardwareInterface>PositionJointInterface</hardwareInterface>
      </joint>
      <actuator name="${prefix}joint_a6_motor">
        <mechanicalReduction>1</mechanicalReduction>
      </actuator>
    </transmission>

  </xacro:macro>
</robot>
